2020-04-10 17:21:15,990 INFO: Microblog startup [in C:\Users\S.Venkateswaran\Desktop\microblog\app\__init__.py:55]
2020-04-10 17:26:44,798 INFO: Microblog startup [in C:\Users\S.Venkateswaran\Desktop\microblog\app\__init__.py:55]
2020-04-10 17:26:47,738 INFO: Microblog startup [in C:\Users\S.Venkateswaran\Desktop\microblog\app\__init__.py:55]
2020-04-10 17:31:20,661 INFO: Microblog startup [in C:\Users\S.Venkateswaran\Desktop\microblog\app\__init__.py:55]
2020-04-10 17:32:44,534 INFO: Microblog startup [in C:\Users\S.Venkateswaran\Desktop\microblog\app\__init__.py:55]
2020-04-10 17:35:15,518 INFO: Microblog startup [in C:\Users\S.Venkateswaran\Desktop\microblog\app\__init__.py:55]
2020-04-10 19:20:18,131 INFO: Microblog startup [in C:\Users\S.Venkateswaran\Desktop\microblog\app\__init__.py:55]
2020-04-10 19:21:23,085 INFO: Microblog startup [in C:\Users\S.Venkateswaran\Desktop\microblog\app\__init__.py:55]
2020-04-10 19:22:59,672 INFO: Microblog startup [in C:\Users\S.Venkateswaran\Desktop\microblog\app\__init__.py:55]
2020-04-10 19:24:00,989 INFO: Microblog startup [in C:\Users\S.Venkateswaran\Desktop\microblog\app\__init__.py:55]
2020-04-10 19:25:25,921 INFO: Microblog startup [in C:\Users\S.Venkateswaran\Desktop\microblog\app\__init__.py:55]
2020-04-10 20:09:11,943 INFO: Microblog startup [in C:\Users\S.Venkateswaran\Desktop\microblog\app\__init__.py:55]
2020-04-10 20:09:46,780 INFO: Microblog startup [in C:\Users\S.Venkateswaran\Desktop\microblog\app\__init__.py:55]
2020-04-10 20:10:11,177 INFO: Microblog startup [in C:\Users\S.Venkateswaran\Desktop\microblog\app\__init__.py:55]
2020-04-10 20:10:41,567 ERROR: Exception on /reset_password_request [POST] [in c:\users\s.venkateswaran\desktop\microblog\venv\lib\site-packages\flask\app.py:1890]
Traceback (most recent call last):
  File "c:\users\s.venkateswaran\desktop\microblog\venv\lib\site-packages\flask\app.py", line 2446, in wsgi_app
    response = self.full_dispatch_request()
  File "c:\users\s.venkateswaran\desktop\microblog\venv\lib\site-packages\flask\app.py", line 1951, in full_dispatch_request
    rv = self.handle_user_exception(e)
  File "c:\users\s.venkateswaran\desktop\microblog\venv\lib\site-packages\flask\app.py", line 1820, in handle_user_exception
    reraise(exc_type, exc_value, tb)
  File "c:\users\s.venkateswaran\desktop\microblog\venv\lib\site-packages\flask\_compat.py", line 39, in reraise
    raise value
  File "c:\users\s.venkateswaran\desktop\microblog\venv\lib\site-packages\flask\app.py", line 1949, in full_dispatch_request
    rv = self.dispatch_request()
  File "c:\users\s.venkateswaran\desktop\microblog\venv\lib\site-packages\flask\app.py", line 1935, in dispatch_request
    return self.view_functions[rule.endpoint](**req.view_args)
  File "C:\Users\S.Venkateswaran\Desktop\microblog\app\routes.py", line 166, in reset_password_request
    if form.validate_on_submit():
  File "c:\users\s.venkateswaran\desktop\microblog\venv\lib\site-packages\flask_wtf\form.py", line 100, in validate_on_submit
    return self.is_submitted() and self.validate()
  File "c:\users\s.venkateswaran\desktop\microblog\venv\lib\site-packages\wtforms\form.py", line 310, in validate
    return super(Form, self).validate(extra)
  File "c:\users\s.venkateswaran\desktop\microblog\venv\lib\site-packages\wtforms\form.py", line 152, in validate
    if not field.validate(self, extra):
  File "c:\users\s.venkateswaran\desktop\microblog\venv\lib\site-packages\wtforms\fields\core.py", line 206, in validate
    stop_validation = self._run_validation_chain(form, chain)
  File "c:\users\s.venkateswaran\desktop\microblog\venv\lib\site-packages\wtforms\fields\core.py", line 226, in _run_validation_chain
    validator(form, self)
TypeError: __init__() takes from 1 to 2 positional arguments but 3 were given
2020-04-10 20:11:20,563 INFO: Microblog startup [in C:\Users\S.Venkateswaran\Desktop\microblog\app\__init__.py:55]
2020-04-10 20:12:01,790 ERROR: Exception on /reset_password_request [POST] [in c:\users\s.venkateswaran\desktop\microblog\venv\lib\site-packages\flask\app.py:1890]
Traceback (most recent call last):
  File "c:\users\s.venkateswaran\desktop\microblog\venv\lib\site-packages\flask\app.py", line 2446, in wsgi_app
    response = self.full_dispatch_request()
  File "c:\users\s.venkateswaran\desktop\microblog\venv\lib\site-packages\flask\app.py", line 1951, in full_dispatch_request
    rv = self.handle_user_exception(e)
  File "c:\users\s.venkateswaran\desktop\microblog\venv\lib\site-packages\flask\app.py", line 1820, in handle_user_exception
    reraise(exc_type, exc_value, tb)
  File "c:\users\s.venkateswaran\desktop\microblog\venv\lib\site-packages\flask\_compat.py", line 39, in reraise
    raise value
  File "c:\users\s.venkateswaran\desktop\microblog\venv\lib\site-packages\flask\app.py", line 1949, in full_dispatch_request
    rv = self.dispatch_request()
  File "c:\users\s.venkateswaran\desktop\microblog\venv\lib\site-packages\flask\app.py", line 1935, in dispatch_request
    return self.view_functions[rule.endpoint](**req.view_args)
  File "C:\Users\S.Venkateswaran\Desktop\microblog\app\routes.py", line 166, in reset_password_request
    if form.validate_on_submit():
  File "c:\users\s.venkateswaran\desktop\microblog\venv\lib\site-packages\flask_wtf\form.py", line 100, in validate_on_submit
    return self.is_submitted() and self.validate()
  File "c:\users\s.venkateswaran\desktop\microblog\venv\lib\site-packages\wtforms\form.py", line 310, in validate
    return super(Form, self).validate(extra)
  File "c:\users\s.venkateswaran\desktop\microblog\venv\lib\site-packages\wtforms\form.py", line 152, in validate
    if not field.validate(self, extra):
  File "c:\users\s.venkateswaran\desktop\microblog\venv\lib\site-packages\wtforms\fields\core.py", line 206, in validate
    stop_validation = self._run_validation_chain(form, chain)
  File "c:\users\s.venkateswaran\desktop\microblog\venv\lib\site-packages\wtforms\fields\core.py", line 226, in _run_validation_chain
    validator(form, self)
TypeError: __init__() takes from 1 to 2 positional arguments but 3 were given
2020-04-10 20:23:53,871 INFO: Microblog startup [in C:\Users\S.Venkateswaran\Desktop\microblog\app\__init__.py:55]
2020-04-10 20:56:44,934 INFO: Microblog startup [in C:\Users\S.Venkateswaran\Desktop\microblog\app\__init__.py:60]
2020-04-10 20:57:38,330 ERROR: Exception on /user/susan [GET] [in c:\users\s.venkateswaran\desktop\microblog\venv\lib\site-packages\flask\app.py:1890]
Traceback (most recent call last):
  File "c:\users\s.venkateswaran\desktop\microblog\venv\lib\site-packages\flask\app.py", line 2446, in wsgi_app
    response = self.full_dispatch_request()
  File "c:\users\s.venkateswaran\desktop\microblog\venv\lib\site-packages\flask\app.py", line 1951, in full_dispatch_request
    rv = self.handle_user_exception(e)
  File "c:\users\s.venkateswaran\desktop\microblog\venv\lib\site-packages\flask\app.py", line 1820, in handle_user_exception
    reraise(exc_type, exc_value, tb)
  File "c:\users\s.venkateswaran\desktop\microblog\venv\lib\site-packages\flask\_compat.py", line 39, in reraise
    raise value
  File "c:\users\s.venkateswaran\desktop\microblog\venv\lib\site-packages\flask\app.py", line 1949, in full_dispatch_request
    rv = self.dispatch_request()
  File "c:\users\s.venkateswaran\desktop\microblog\venv\lib\site-packages\flask\app.py", line 1935, in dispatch_request
    return self.view_functions[rule.endpoint](**req.view_args)
  File "c:\users\s.venkateswaran\desktop\microblog\venv\lib\site-packages\flask_login\utils.py", line 272, in decorated_view
    return func(*args, **kwargs)
  File "C:\Users\S.Venkateswaran\Desktop\microblog\app\routes.py", line 92, in user
    return render_template('user.html', user=user, posts=posts.item, next_url=next_url, prev_url=prev_url)
AttributeError: 'Pagination' object has no attribute 'item'
2020-04-10 20:59:17,113 INFO: Microblog startup [in C:\Users\S.Venkateswaran\Desktop\microblog\app\__init__.py:60]
2020-04-10 21:00:01,886 INFO: Microblog startup [in C:\Users\S.Venkateswaran\Desktop\microblog\app\__init__.py:60]
2020-04-10 21:02:47,646 INFO: Microblog startup [in C:\Users\S.Venkateswaran\Desktop\microblog\app\__init__.py:60]
2020-04-11 00:31:23,827 INFO: Microblog startup [in C:\Users\S.Venkateswaran\Desktop\microblog\app\__init__.py:52]
2020-04-11 00:31:31,606 ERROR: Exception on / [GET] [in c:\users\s.venkateswaran\desktop\microblog\venv\lib\site-packages\flask\app.py:1890]
Traceback (most recent call last):
  File "c:\users\s.venkateswaran\desktop\microblog\venv\lib\site-packages\flask\app.py", line 2446, in wsgi_app
    response = self.full_dispatch_request()
  File "c:\users\s.venkateswaran\desktop\microblog\venv\lib\site-packages\flask\app.py", line 1951, in full_dispatch_request
    rv = self.handle_user_exception(e)
  File "c:\users\s.venkateswaran\desktop\microblog\venv\lib\site-packages\flask\app.py", line 1820, in handle_user_exception
    reraise(exc_type, exc_value, tb)
  File "c:\users\s.venkateswaran\desktop\microblog\venv\lib\site-packages\flask\_compat.py", line 39, in reraise
    raise value
  File "c:\users\s.venkateswaran\desktop\microblog\venv\lib\site-packages\flask\app.py", line 1947, in full_dispatch_request
    rv = self.preprocess_request()
  File "c:\users\s.venkateswaran\desktop\microblog\venv\lib\site-packages\flask\app.py", line 2241, in preprocess_request
    rv = func()
  File "C:\Users\S.Venkateswaran\Desktop\microblog\app\routes.py", line 18, in before_request
    g.locale = str(get_locale())
  File "c:\users\s.venkateswaran\desktop\microblog\venv\lib\site-packages\flask_babel\__init__.py", line 251, in get_locale
    rv = babel.locale_selector_func()
  File "C:\Users\S.Venkateswaran\Desktop\microblog\app\__init__.py", line 58, in get_locale
    return es
NameError: name 'es' is not defined
2020-04-11 00:34:34,505 INFO: Microblog startup [in C:\Users\S.Venkateswaran\Desktop\microblog\app\__init__.py:52]
2020-04-11 00:36:23,712 INFO: Microblog startup [in C:\Users\S.Venkateswaran\Desktop\microblog\app\__init__.py:52]
